Workbook
Name Invoices: #REF!
Name Invoices: Wrapup31[]
Name Invoices: Wrapup[]
Name Summary: #REF!
Name Summary: Wrapup31[]
Name Summary: Wrapup[]

Sheet Summary
A1: Invoices Process Report - Design Projects
A4: Consultant | B4: Framework status | C4: Framework ID | D4: Frame Work Contract | E4: Value | F4: Duration | G4: Start Date | H4: Finsih Date | I4: Committed | J4: Remaining from framework | K4: Invoices w/out VAT | L4: Earned value | M4: Remaining to Invoice
A5: Dorsch food | B5: Closed | C5: MLTX-01-085 | D5: 2547 | E5: =22992640/1.15 -> 19993600 | F5: 24M | G5: 45085 | H5: 45816 | I5: =SUMIF(Maindata[Framework ID],Wrapup31[[#This Row],[Framework ID]],Maindata[Project Total amount]) -> 19558881 | J5: =E5-I5 -> 434719 | K5: =SUMIF(Currentinvoices[Framework ID],Wrapup31[[#This Row],[Framework ID]],Currentinvoices[Invoices Submitted Without VAT]) -> 18891266 | L5: =SUMIF(Currentinvoices[Framework ID],Wrapup31[[#This Row],[Framework ID]],Currentinvoices[Earned Value]) -> 19558881 | M5: =Wrapup31[[#This Row],[Earned value]]-Wrapup31[[#This Row],[Invoices w/out VAT]] -> 667615.42
A6: SYSTRA | B6: Closed | C6: MLTX-01-102 | D6: 2672 | E6: 15054089 | F6: 24M | G6: =EDATE(Wrapup31[[#This Row],[Finsih Date]], - 24) -> 45342 | H6: 46073 | I6: =SUMIF(Maindata[Framework ID],Wrapup31[[#This Row],[Framework ID]],Maindata[Project Total amount]) -> 15054089 | J6: =E6-I6 -> 0 | K6: =SUMIF(Currentinvoices[Framework ID],Wrapup31[[#This Row],[Framework ID]],Currentinvoices[Invoices Submitted Without VAT]) -> 15054089 | L6: =SUMIF(Currentinvoices[Framework ID],Wrapup31[[#This Row],[Framework ID]],Currentinvoices[Earned Value]) -> 15054089 | M6: =Wrapup31[[#This Row],[Earned value]]-Wrapup31[[#This Row],[Invoices w/out VAT]] -> 0
A7: EGEC - NIS2 | B7: Ongoing | C7: MLTX-01-099 | D7: 2709 | E7: 19979840 | F7: 48M | G7: 45421 | H7: 46882 | I7: =SUMIF(Maindata[Framework ID],Wrapup31[[#This Row],[Framework ID]],Maindata[Project Total amount]) -> 18497269 | J7: =E7-I7 -> 1482571 | K7: =SUMIF(Currentinvoices[Framework ID],Wrapup31[[#This Row],[Framework ID]],Currentinvoices[Invoices Submitted Without VAT]) -> 18147018 | L7: =SUMIF(Currentinvoices[Framework ID],Wrapup31[[#This Row],[Framework ID]],Currentinvoices[Earned Value]) -> 18467769 | M7: =Wrapup31[[#This Row],[Earned value]]-Wrapup31[[#This Row],[Invoices w/out VAT]] -> 320751.45
A8: ENGICON | B8: Closed | C8: RDH4-00-001 | D8: 2666 | E8: 27837620 | F8: 10M | G8: =EDATE(Wrapup31[[#This Row],[Finsih Date]], - 10) -> 45444 | H8: 45748 | I8: =SUMIF(Maindata[Framework ID],Wrapup31[[#This Row],[Framework ID]],Maindata[Project Total amount]) -> 27837620 | J8: =E8-I8 -> 0 | K8: =SUMIF(Currentinvoices[Framework ID],Wrapup31[[#This Row],[Framework ID]],Currentinvoices[Invoices Submitted Without VAT]) -> 25053858 | L8: =SUMIF(Currentinvoices[Framework ID],Wrapup31[[#This Row],[Framework ID]],Currentinvoices[Earned Value]) -> 27837620 | M8: =Wrapup31[[#This Row],[Earned value]]-Wrapup31[[#This Row],[Invoices w/out VAT]] -> 2783762
A9: EGEC - WAS | B9: Ongoing | C9: WAS1-01-039 | D9: TBA | E9: 9799000 | F9: 24M | G9: 45608 | H9: 46338 | I9: =SUMIF(Maindata[Framework ID],Wrapup31[[#This Row],[Framework ID]],Maindata[Project Total amount]) -> 7075670 | J9: =E9-I9 -> 2723330 | K9: =SUMIF(Currentinvoices[Framework ID],Wrapup31[[#This Row],[Framework ID]],Currentinvoices[Invoices Submitted Without VAT]) -> 7075670.9 | L9: =SUMIF(Currentinvoices[Framework ID],Wrapup31[[#This Row],[Framework ID]],Currentinvoices[Earned Value]) -> 7075670 | M9: =Wrapup31[[#This Row],[Earned value]]-Wrapup31[[#This Row],[Invoices w/out VAT]] -> -0.9
A10: ENGICON - Package1 | B10: Ongoing | C10: MLTX-01-098 | D10: 2891 | E10: 19856000 | F10: 60M | G10: 45700 | H10: 47526 | I10: =SUMIF(Maindata[Framework ID],Wrapup31[[#This Row],[Framework ID]],Maindata[Project Total amount]) -> 16551382 | J10: =E10-I10 -> 3304618 | K10: =SUMIF(Currentinvoices[Framework ID],Wrapup31[[#This Row],[Framework ID]],Currentinvoices[Invoices Submitted Without VAT]) -> 14962621 | L10: =SUMIF(Currentinvoices[Framework ID],Wrapup31[[#This Row],[Framework ID]],Currentinvoices[Earned Value]) -> 15549823 | M10: =Wrapup31[[#This Row],[Earned value]]-Wrapup31[[#This Row],[Invoices w/out VAT]] -> 587202.15 | BP10: a | BQ10: b | BR10: c
A11: ENGICON - RDH4 | B11: Closed | C11: RDH4-01-002 | D11: TBA | E11: 7025000 | F11: 24M | G11: =EDATE(Wrapup31[[#This Row],[Finsih Date]], - 24) -> 45617 | H11: 46347 | I11: =SUMIF(Maindata[Framework ID],Wrapup31[[#This Row],[Framework ID]],Maindata[Project Total amount]) -> 7025000 | J11: =E11-I11 -> 0 | K11: =SUMIF(Currentinvoices[Framework ID],Wrapup31[[#This Row],[Framework ID]],Currentinvoices[Invoices Submitted Without VAT]) -> 7024999.8 | L11: =SUMIF(Currentinvoices[Framework ID],Wrapup31[[#This Row],[Framework ID]],Currentinvoices[Earned Value]) -> 14050000 | M11: =Wrapup31[[#This Row],[Earned value]]-Wrapup31[[#This Row],[Invoices w/out VAT]] -> 7025000.2 | BO11: a | BP11: 15 | BQ11: 13 | BR11: 15
A12: Dar AlRiyadh 2 | B12: Ongoing | C12: MLTX-01-100 | D12: 2814 | E12: 59999686 | F12: 60M | G12: 45567 | H12: 47393 | I12: =SUMIF(Maindata[Framework ID],Wrapup31[[#This Row],[Framework ID]],Maindata[Project Total amount]) -> 0 | J12: =E12-I12 -> 59999686 | K12: =SUMIF(Currentinvoices[Framework ID],Wrapup31[[#This Row],[Framework ID]],Currentinvoices[Invoices Submitted Without VAT]) -> 22554552 | L12: =SUMIF(Currentinvoices[Framework ID],Wrapup31[[#This Row],[Framework ID]],Currentinvoices[Earned Value]) -> 0 | M12: =Wrapup31[[#This Row],[Earned value]]-Wrapup31[[#This Row],[Invoices w/out VAT]] -> -22554552
A13: Meinhardt (KHJ - FOOD) | B13: Ongoing | C13: KHJ1-01-020 | D13: 2966 | E13: 14990000 | F13: 24M | G13: 45832 | H13: 46562 | I13: =SUMIF(Maindata[Framework ID],Wrapup31[[#This Row],[Framework ID]],Maindata[Project Total amount]) -> 11685630 | J13: =E13-I13 -> 3304370 | K13: =SUMIF(Currentinvoices[Framework ID],Wrapup31[[#This Row],[Framework ID]],Currentinvoices[Invoices Submitted Without VAT]) -> 3939904.9 | L13: =SUMIF(Currentinvoices[Framework ID],Wrapup31[[#This Row],[Framework ID]],Currentinvoices[Earned Value]) -> 4469255 | M13: =Wrapup31[[#This Row],[Earned value]]-Wrapup31[[#This Row],[Invoices w/out VAT]] -> 529350.07
A14: Meinhardt (RDH1-01-006) | B14: Ongoing | C14: RDH1-01-006 | D14: 3172 | E14: 25298852 | G14: 46057 | H14: 46602 | I14: =SUMIF(Maindata[Framework ID],Wrapup31[[#This Row],[Framework ID]],Maindata[Project Total amount]) -> 25298852 | J14: =E14-I14 -> 0.17 | K14: =SUMIF(Currentinvoices[Framework ID],Wrapup31[[#This Row],[Framework ID]],Currentinvoices[Invoices Submitted Without VAT]) -> 7469770.1 | L14: =SUMIF(Currentinvoices[Framework ID],Wrapup31[[#This Row],[Framework ID]],Currentinvoices[Earned Value]) -> 12009587 | M14: =Wrapup31[[#This Row],[Earned value]]-Wrapup31[[#This Row],[Invoices w/out VAT]] -> 4539816.6
A15: ENGICON - RDH4 PH2 | B15: Ongoing | C15: RDH4-01-003 | D15: 3026 | E15: 59500000 | F15: 36M | G15: 45858 | H15: 46954 | I15: =SUMIF(Maindata[Framework ID],Wrapup31[[#This Row],[Framework ID]],Maindata[Project Total amount]) -> 39471610 | J15: =E15-I15 -> 20028390 | K15: =SUMIF(Currentinvoices[Framework ID],Wrapup31[[#This Row],[Framework ID]],Currentinvoices[Invoices Submitted Without VAT]) -> 27536518 | L15: =SUMIF(Currentinvoices[Framework ID],Wrapup31[[#This Row],[Framework ID]],Currentinvoices[Earned Value]) -> 28199915 | M15: =Wrapup31[[#This Row],[Earned value]]-Wrapup31[[#This Row],[Invoices w/out VAT]] -> 663396.91 | BP15: =MOD(SUM(BP11:BR11),2) -> 1
A16: AlDar International (KHJ - FOOD2) | B16: Ongoing | C16: KHJ-01-027 | D16: 3041 | E16: 11637180 | F16: 24M | G16: =EDATE(Wrapup31[[#This Row],[Finsih Date]], - 24) -> 45879 | H16: 46609 | I16: =SUMIF(Maindata[Framework ID],Wrapup31[[#This Row],[Framework ID]],Maindata[Project Total amount]) -> 7146100 | J16: =E16-I16 -> 4491080 | K16: =SUMIF(Currentinvoices[Framework ID],Wrapup31[[#This Row],[Framework ID]],Currentinvoices[Invoices Submitted Without VAT]) -> 6043100.3 | L16: =SUMIF(Currentinvoices[Framework ID],Wrapup31[[#This Row],[Framework ID]],Currentinvoices[Earned Value]) -> 7146100 | M16: =Wrapup31[[#This Row],[Earned value]]-Wrapup31[[#This Row],[Invoices w/out VAT]] -> 1102999.7
A17: ENGICON - Logistics | B17: Ongoing | C17: MLTX-01-117 | D17: 3042 | E17: 27800000 | F17: 24M | G17: =EDATE(Wrapup31[[#This Row],[Finsih Date]], - 24) -> 45868 | H17: 46598 | I17: =SUMIF(Maindata[Framework ID],Wrapup31[[#This Row],[Framework ID]],Maindata[Project Total amount]) -> 23907174 | J17: =E17-I17 -> 3892826 | K17: =SUMIF(Currentinvoices[Framework ID],Wrapup31[[#This Row],[Framework ID]],Currentinvoices[Invoices Submitted Without VAT]) -> 19924325 | L17: =SUMIF(Currentinvoices[Framework ID],Wrapup31[[#This Row],[Framework ID]],Currentinvoices[Earned Value]) -> 22967072 | M17: =Wrapup31[[#This Row],[Earned value]]-Wrapup31[[#This Row],[Invoices w/out VAT]] -> 3042746.9
A18: EGEC - NIS3 | B18: Ongoing | D18: 3020 | E18: 19955000 | F18: 48M | G18: =EDATE(Wrapup31[[#This Row],[Finsih Date]], - 48) -> 45848 | H18: 47309 | I18: =SUMIF(Maindata[Framework ID],Wrapup31[[#This Row],[Framework ID]],Maindata[Project Total amount]) -> 0 | J18: =E18-I18 -> 19955000 | K18: =SUMIF(Currentinvoices[Framework ID],Wrapup31[[#This Row],[Framework ID]],Currentinvoices[Invoices Submitted Without VAT]) -> 0 | L18: =SUMIF(Currentinvoices[Framework ID],Wrapup31[[#This Row],[Framework ID]],Currentinvoices[Earned Value]) -> 0 | M18: =Wrapup31[[#This Row],[Earned value]]-Wrapup31[[#This Row],[Invoices w/out VAT]] -> 0
A19: TYPSA- (KHJ-AMIC) | B19: Ongoing | C19: KHJ2-01-001 | E19: 57332139 | I19: =SUMIF(Maindata[Framework ID],Wrapup31[[#This Row],[Framework ID]],Maindata[Project Total amount]) -> 51542409 | J19: =E19-I19 -> 5789730.5 | K19: =SUMIF(Currentinvoices[Framework ID],Wrapup31[[#This Row],[Framework ID]],Currentinvoices[Invoices Submitted Without VAT]) -> 7579488.4 | L19: =SUMIF(Currentinvoices[Framework ID],Wrapup31[[#This Row],[Framework ID]],Currentinvoices[Earned Value]) -> 5647031.9 | M19: =Wrapup31[[#This Row],[Earned value]]-Wrapup31[[#This Row],[Invoices w/out VAT]] -> -1932456.5
A20: Total | E20: =SUBTOTAL(109,Wrapup31[Value]) -> 3.261477e+08 | I20: =SUBTOTAL(109,Wrapup31[[Committed ]]) -> 2.011761e+08 | J20: =SUBTOTAL(109,Wrapup31[Remaining from framework]) -> 1.249716e+08 | K20: =SUBTOTAL(109,Wrapup31[Invoices w/out VAT]) -> 1.3523297e+08 | L20: =SUBTOTAL(109,Wrapup31[Earned value]) -> 1.2153222e+08

Sheet Invoices (2)
A1: CASH FLOW OVERVIEW OF RUNNING PROJECTS
A3: Consultant | B3: Framework ID | C3: S/No. | D3: Projects | E3: Project ID | F3: Task Value | G3: Invoice # 1 date | H3: Invoice # 1 amount | I3: Invoice # 1 vat | J3: Invoice # 1 total | K3: Invoice # 2 date | L3: Invoice # 2 amount | M3: Invoice # 2 vat | N3: Invoice # 2 total | O3: Invoice # 3 date | P3: Invoice # 3 amount | Q3: Invoice # 3 vat | R3: Invoice # 3 total | S3: Invoice # 4 date | T3: Invoice # 4 amount | U3: Invoice # 4 vat | V3: Invoice # 4 total | W3: Invoice # 5 date | X3: Invoice # 5 amount | Y3: Invoice # 5 vat | Z3: Invoice # 5 total | AA3: Invoice # 6 date | AB3: Invoice # 6 amount | AC3: Invoice # 6 vat | AD3: Invoice # 6 total | AE3: Invoice # 7 date | AF3: Invoice # 7 amount | AG3: Invoice # 7 vat | AH3: Invoice # 7 total | AI3: Invoice # 8 date | AJ3: Invoice # 8 amount | AK3: Invoice # 8 vat | AL3: Invoice # 8 total | AM3: Invoice # 9 date | AN3: Invoice # 9 amount | AO3: Invoice # 9 vat | AP3: Invoice # 9 total | AQ3: Invoice # 10 date | AR3: Invoice # 10 amount | AS3: Invoice # 10 vat | AT3: Invoice # 10 total | AU3: Invoice # 11 date | AV3: Invoice # 11 amount | AW3: Invoice # 11 vat | AX3: Invoice # 11 total | AY3: Invoice # 12 date | AZ3: Invoice # 12 amount | BA3: Invoice # 12 vat | BB3: Invoice # 12 total | BC3: Invoice # 13 date | BD3: Invoice # 13 amount | BE3: Invoice # 13 vat | BF3: Invoice # 13 total | BG3: Invoice # 14 date | BH3: Invoice # 14 amount | BI3: Invoice # 14 vat | BJ3: Invoice # 14 total | BK3: Invoice # 15 date | BL3: Invoice # 15 amount | BM3: Invoice # 15 vat | BN3: Invoice # 15 total | BO3: Invoice # 16 date | BP3: Invoice # 16 amount | BQ3: Invoice # 16 vat | BR3: Invoice # 16 total | BS3: Invoice # 17 date | BT3: Invoice # 17 amount | BU3: Invoice # 17 vat | BV3: Invoice # 17 total | BW3: Invoice # 18 date | BX3: Invoice # 18 amount | BY3: Invoice # 18 vat | BZ3: Invoice # 18 total | CA3: Invoice # 19 date | CB3: Invoice # 19 amount | CC3: Invoice # 19 vat | CD3: Invoice # 19 total | CE3: Invoice # 20 date | CF3: Invoice # 20 amount | CG3: Invoice # 20 vat | CH3: Invoice # 20 total | CI3: Invoice # 21 date | CJ3: Invoice # 21 amount | CK3: Invoice # 21 vat | CL3: Invoice # 21 total | CM3: Invoice # 22 date | CN3: Invoice # 22 amount | CO3: Invoice # 22 vat | CP3: Invoice # 22 total | CQ3: Invoice # 23 date | CR3: Invoice # 23 amount | CS3: Invoice # 23 vat | CT3: Invoice # 23 total | CU3: Invoice # 24 date | CV3: Invoice # 24 amount | CW3: Invoice # 24 vat | CX3: Invoice # 24 total | CY3: Invoice # 25 date | CZ3: Invoice # 25 amount | DA3: Invoice # 25 vat | DB3: Invoice # 25 total | DC3: Remarks | DD3: Task Value2 | DE3: VAT | DF3: Total | DG3: Invoices Submitted Without VAT | DH3: Invoices Submitted With VAT | DI3: % Completion | DJ3: Earned Value | DK3: Remaining Value
A4: Dorsch food | B4: MLTX-01-085 | C4: 1 | D4: Jeddah 2 - Food Cluster - RBF 450 & 900 m2 | E4: JDH2-01-016 | F4: 877779 | G4: 45225 | H4: 416905 | I4: =H4*15% -> 62535.75 | J4: =H4+I4 -> 479440.75 | O4: 45398 | P4: 368699 | Q4: =P4*15% -> 55304.85 | R4: =P4+Q4 -> 424003.85 | DD4: =F4 -> 877779 | DE4: =DD4*15% -> 131666.85 | DF4: =DD4+DE4 -> 1009445.8 | DG4: =SUMPRODUCT((MOD(COLUMN(G4:DB4)-COLUMN(G4),4)=1)*G4:DB4) -> 785604 | DH4: =SUMPRODUCT((MOD(COLUMN(G4:DB4)-COLUMN(H4),4)=2)*G4:DB4) -> 903444.6 | DI4: 1 | DJ4: =DI4*DD4 -> 877779 | DK4: =DJ4-DG4 -> 92175
A5: Dorsch food | B5: MLTX-01-085 | C5: 2 | D5: Jeddah Food Cluster - Masterplan Update & Lands Selection at Jeddah 2nd & 3rd Ind. Cities | E5: MLTX-01-093 | F5: 1403611 | G5: 45225 | H5: 1403611 | I5: =H5*15% -> 210541.65 | J5: =H5+I5 -> 1614152.6 | DD5: =F5 -> 1403611 | DE5: =DD5*15% -> 210541.65 | DF5: =DD5+DE5 -> 1614152.6 | DG5: =SUMPRODUCT((MOD(COLUMN(G5:DB5)-COLUMN(G5),4)=1)*G5:DB5) -> 1403611 | DH5: =SUMPRODUCT((MOD(COLUMN(G5:DB5)-COLUMN(H5),4)=2)*G5:DB5) -> 1614152.6 | DI5: 1 | DJ5: =DI5*DD5 -> 1403611 | DK5: =DJ5-DG5 -> 0
A6: Dorsch food | B6: MLTX-01-085 | C6: 3 | D6: Jeddah 3 - Design of Shared Dry & Cold Storage Warehouses in Jeddah 3 Ind. City | E6: JDH3-01-021 | F6: 2999654 | G6: 45225 | H6: 1377997 | I6: =H6*15% -> 206699.55 | J6: =H6+I6 -> 1584696.6 | O6: 45398 | P6: 1297326 | Q6: =P6*15% -> 194598.9 | R6: =P6+Q6 -> 1491924.9 | DD6: =F6 -> 2999654 | DE6: =DD6*15% -> 449948.1 | DF6: =DD6+DE6 -> 3449602.1 | DG6: =SUMPRODUCT((MOD(COLUMN(G6:DB6)-COLUMN(G6),4)=1)*G6:DB6) -> 2675323 | DH6: =SUMPRODUCT((MOD(COLUMN(G6:DB6)-COLUMN(H6),4)=2)*G6:DB6) -> 3076621.5 | DI6: 1 | DJ6: =DI6*DD6 -> 2999654 | DK6: =DJ6-DG6 -> 324331
A7: Dorsch food | B7: MLTX-01-085 | C7: 4 | D7: Master planning a logistic area in Dammam 2 | E7: DAM2-01-026 | F7: 4125000 | K7: 45370 | L7: 682683 | M7: =L7*15% -> 102402.45 | N7: =L7+M7 -> 785085.45 | S7: 45435 | T7: 1379810.1 | U7: =T7*15% -> 206971.52 | V7: =T7+U7 -> 1586781.6 | AA7: 45471 | AB7: 2062506.5 | AC7: =AB7*15% -> 309375.98 | AD7: =AB7+AC7 -> 2371882.5 | DD7: =F7 -> 4125000 | DE7: =DD7*15% -> 618750 | DF7: =DD7+DE7 -> 4743750 | DG7: =SUMPRODUCT((MOD(COLUMN(G7:DB7)-COLUMN(G7),4)=1)*G7:DB7) -> 4124999.6 | DH7: =SUMPRODUCT((MOD(COLUMN(G7:DB7)-COLUMN(H7),4)=2)*G7:DB7) -> 4743749.6 | DI7: 1 | DJ7: =DI7*DD7 -> 4125000 | DK7: =DJ7-DG7 -> 0.37
A8: Dorsch food | B8: MLTX-01-085 | C8: 5 | D8: Hydrology Study for preventing Jeddah 4th Industrial City from floods and stormwater | E8: JDH4-01-040 | F8: 404258 | S8: 45435 | T8: 125226 | U8: =T8*15% -> 18783.9 | V8: =T8+U8 -> 144009.9 | AE8: 45537 | AF8: 279032 | AG8: =AF8*15% -> 41854.8 | AH8: =AF8+AG8 -> 320886.8 | DD8: =F8 -> 404258 | DE8: =DD8*15% -> 60638.7 | DF8: =DD8+DE8 -> 464896.7 | DG8: =SUMPRODUCT((MOD(COLUMN(G8:DB8)-COLUMN(G8),4)=1)*G8:DB8) -> 404258 | DH8: =SUMPRODUCT((MOD(COLUMN(G8:DB8)-COLUMN(H8),4)=2)*G8:DB8) -> 464896.7 | DI8: 1 | DJ8: =DI8*DD8 -> 404258 | DK8: =DJ8-DG8 -> 0
A9: Dorsch food | B9: MLTX-01-085 | C9: 6 | D9: Completing the infrastructure networks and residential neighborhood in the 2nd industrial city in Dammam | E9: DAM2-02-027 | F9: 6968306 | W9: 45451 | X9: 2539503 | Y9: =X9*15% -> 380925.45 | Z9: =X9+Y9 -> 2920428.5 | AI9: 45540 | AJ9: 1602086 | AK9: =AJ9*15% -> 240312.9 | AL9: =AJ9+AK9 -> 1842398.9 | BC9: 45728 | BD9: 2826718 | BE9: =BD9*15% -> 424007.69 | BF9: =BD9+BE9 -> 3250725.6 | DD9: =F9 -> 6968306 | DE9: =DD9*15% -> 1045245.9 | DF9: =DD9+DE9 -> 8013551.9 | DG9: =SUMPRODUCT((MOD(COLUMN(G9:DB9)-COLUMN(G9),4)=1)*G9:DB9) -> 6968307 | DH9: =SUMPRODUCT((MOD(COLUMN(G9:DB9)-COLUMN(H9),4)=2)*G9:DB9) -> 8013553 | DI9: 1 | DJ9: =DI9*DD9 -> 6968306 | DK9: =DJ9-DG9 -> -0.95
A10: Dorsch food | B10: MLTX-01-085 | C10: 7 | D10: Reviewing the masterplan for alkhrj nd. City | F10: 174000 | W10: 45451 | X10: 58000.11 | Y10: =X10*15% -> 8700.0165 | Z10: =X10+Y10 -> 66700.126 | AA10: 45471 | AB10: 115999.89 | AC10: =AB10*15% -> 17399.983 | AD10: =AB10+AC10 -> 133399.87 | DD10: =F10 -> 174000 | DE10: =DD10*15% -> 26100 | DF10: =DD10+DE10 -> 200100 | DG10: =SUMPRODUCT((MOD(COLUMN(G10:DB10)-COLUMN(G10),4)=1)*G10:DB10) -> 174000 | DH10: =SUMPRODUCT((MOD(COLUMN(G10:DB10)-COLUMN(H10),4)=2)*G10:DB10) -> 200100 | DI10: 1 | DJ10: =DI10*DD10 -> 174000 | DK10: =DJ10-DG10 -> 0
A11: Dorsch food | B11: MLTX-01-085 | C11: 8 | D11: Detail MPL and infra Design for the multi-use area in Dammam2 | E11: DAM2-01-029 | F11: 836000 | AM11: 45572 | AN11: 302500.8 | AO11: =AN11*15% -> 45375.12 | AP11: =AN11+AO11 -> 347875.92 | AQ11: 45650 | AR11: 533499.2 | AS11: =AR11*15% -> 80024.88 | AT11: =AR11+AS11 -> 613524.08 | DD11: =F11 -> 836000 | DE11: =DD11*15% -> 125400 | DF11: =DD11+DE11 -> 961400 | DG11: =SUMPRODUCT((MOD(COLUMN(G11:DB11)-COLUMN(G11),4)=1)*G11:DB11) -> 836000 | DH11: =SUMPRODUCT((MOD(COLUMN(G11:DB11)-COLUMN(H11),4)=2)*G11:DB11) -> 961400 | DI11: 1 | DJ11: =DI11*DD11 -> 836000 | DK11: =DJ11-DG11 -> 0
A12: Dorsch food | B12: MLTX-01-085 | C12: 9 | D12: Design shared services center - Food cluster | E12: JDH2-01-023 | F12: 1505768 | AM12: 45572 | AN12: 499280 | AO12: =AN12*15% -> 74892 | AP12: =AN12+AO12 -> 574172 | AU12: 45693 | AV12: 500302 | AW12: =AV12*15% -> 75045.3 | AX12: =AV12+AW12 -> 575347.3 | AY12: 45720 | AZ12: 255076 | BA12: =AZ12*15% -> 38261.4 | BB12: =AZ12+BA12 -> 293337.4 | DD12: =F12 -> 1505768 | DE12: =DD12*15% -> 225865.2 | DF12: =DD12+DE12 -> 1731633.2 | DG12: =SUMPRODUCT((MOD(COLUMN(G12:DB12)-COLUMN(G12),4)=1)*G12:DB12) -> 1254658 | DH12: =SUMPRODUCT((MOD(COLUMN(G12:DB12)-COLUMN(H12),4)=2)*G12:DB12) -> 1442856.7 | DI12: 1 | DJ12: =DI12*DD12 -> 1505768 | DK12: =DJ12-DG12 -> 251110
A13: Dorsch food | B13: MLTX-01-085 | C13: 10 | D13: الدراسه القيميه لمشاريع المصانع الجاهزة | F13: 264505 | AQ13: 45650 | AR13: 264505 | AS13: =AR13*15% -> 39675.75 | AT13: =AR13+AS13 -> 304180.75 | DD13: =F13 -> 264505 | DE13: =DD13*15% -> 39675.75 | DF13: =DD13+DE13 -> 304180.75 | DG13: =SUMPRODUCT((MOD(COLUMN(G13:DB13)-COLUMN(G13),4)=1)*G13:DB13) -> 264505 | DH13: =SUMPRODUCT((MOD(COLUMN(G13:DB13)-COLUMN(H13),4)=2)*G13:DB13) -> 304180.75 | DI13: 1 | DJ13: =DI13*DD13 -> 264505 | DK13: =DJ13-DG13 -> 0
A14: SYSTRA | B14: MLTX-01-102 | C14: 1 | D14: Masterplan & Infrstructure Detailed Design For Technology Zones (Jenadryah) | E14: JNDT-01-001 | F14: 6726972 | G14: 45504 | H14: =SYSTRA!H12 -> 672697.82 | I14: =H14*15% -> 100904.67 | J14: =H14+I14 -> 773602.49 | K14: 45511 | L14: =SYSTRA!J12 -> 1681772 | M14: =L14*15% -> 252265.8 | N14: =L14+M14 -> 1934037.8 | O14: 45641 | P14: =SYSTRA!L12 -> 1345449 | Q14: =P14*15% -> 201817.35 | R14: =P14+Q14 -> 1547266.4 | S14: 45727 | T14: =SYSTRA!N12 -> 1681658.8 | U14: =T14*15% -> 252248.82 | V14: =T14+U14 -> 1933907.6 | AA14: 45839 | AB14: =SYSTRA!R12 -> 1345394.4 | AC14: =AB14*15% -> 201809.16 | AD14: =AB14+AC14 -> 1547203.6 | DD14: =F14 -> 6726972 | DE14: =DD14*15% -> 1009045.8 | DF14: =DD14+DE14 -> 7736017.8 | DG14: =SUMPRODUCT((MOD(COLUMN(G14:DB14)-COLUMN(G14),4)=1)*G14:DB14) -> 6726972 | DH14: =SUMPRODUCT((MOD(COLUMN(G14:DB14)-COLUMN(H14),4)=2)*G14:DB14) -> 7736017.8 | DI14: 1 | DJ14: =DI14*DD14 -> 6726972 | DK14: =DJ14-DG14 -> 0
A15: SYSTRA | B15: MLTX-01-102 | C15: 2 | D15: Masterplan & Infrstructure Detailed Design For Technology Zones (Dammam) | E15: DAMT-01-001 | F15: 3300435 | S15: 45727 | T15: =SYSTRA!N27 -> 330043.5 | U15: =T15*15% -> 49506.525 | V15: =T15+U15 -> 379550.03 | W15: 45788 | X15: =SYSTRA!P27 -> 1072641.4 | Y15: =X15*15% -> 160896.21 | Z15: =X15+Y15 -> 1233537.6 | AA15: 45839 | AB15: =SYSTRA!R27 -> 577576.13 | AC15: =AB15*15% -> 86636.42 | AD15: =AB15+AC15 -> 664212.55 | AE15: 46152 | AF15: 1320174 | AG15: =Currentinvoices[[#This Row],[Invoice '# 7 amount]]*15% -> 198026.1 | AH15: =Currentinvoices[[#This Row],[Invoice '# 7 vat]]+Currentinvoices[[#This Row],[Invoice '# 7 amount]] -> 1518200.1 | DD15: =F15 -> 3300435 | DE15: =DD15*15% -> 495065.25 | DF15: =DD15+DE15 -> 3795500.2 | DG15: =SUMPRODUCT((MOD(COLUMN(G15:DB15)-COLUMN(G15),4)=1)*G15:DB15) -> 3300435 | DH15: =SUMPRODUCT((MOD(COLUMN(G15:DB15)-COLUMN(H15),4)=2)*G15:DB15) -> 3795500.2 | DI15: 1 | DJ15: =DI15*DD15 -> 3300435 | DK15: =DJ15-DG15 -> 0
A16: SYSTRA | B16: MLTX-01-102 | C16: 3 | D16: Masterplan & Infrstructure Detailed Design For Technology Zones (Dhahran) | E16: DHRT-01-001 | F16: 3300435 | S16: 45727 | T16: =SYSTRA!N42 -> 330043.5 | U16: =T16*15% -> 49506.525 | V16: =T16+U16 -> 379550.03 | W16: 45788 | X16: =SYSTRA!P42 -> 1072641.4 | Y16: =X16*15% -> 160896.21 | Z16: =X16+Y16 -> 1233537.6 | AA16: 45839 | AB16: =SYSTRA!R42 -> 577576.12 | AC16: =AB16*15% -> 86636.418 | AD16: =AB16+AC16 -> 664212.54 | AE16: 46152 | AF16: 1320174 | AG16: =Currentinvoices[[#This Row],[Invoice '# 7 amount]]*15% -> 198026.1 | AH16: =Currentinvoices[[#This Row],[Invoice '# 7 vat]]+Currentinvoices[[#This Row],[Invoice '# 7 amount]] -> 1518200.1 | DD16: =F16 -> 3300435 | DE16: =DD16*15% -> 495065.25 | DF16: =DD16+DE16 -> 3795500.2 | DG16: =SUMPRODUCT((MOD(COLUMN(G16:DB16)-COLUMN(G16),4)=1)*G16:DB16) -> 3300435 | DH16: =SUMPRODUCT((MOD(COLUMN(G16:DB16)-COLUMN(H16),4)=2)*G16:DB16) -> 3795500.2 | DI16: 1 | DJ16: =DI16*DD16 -> 3300435 | DK16: =DJ16-DG16 -> 0
A17: SYSTRA | B17: MLTX-01-102 | C17: 4 | D17: Technical review and transport planning expertise support for Riyadh Industrial cities 1 & 4 | E17: MLTX-01-111 | F17: 1726247 | W17: 45788 | X17: =SYSTRA!P57 -> 1208358 | Y17: =X17*15% -> 181253.7 | Z17: =X17+Y17 -> 1389611.7 | AA17: 45839 | AB17: =SYSTRA!R57 -> 517889.02 | AC17: =AB17*15% -> 77683.353 | AD17: =AB17+AC17 -> 595572.37 | DD17: =F17 -> 1726247 | DE17: =DD17*15% -> 258937.05 | DF17: =DD17+DE17 -> 1985184.1 | DG17: =SUMPRODUCT((MOD(COLUMN(G17:DB17)-COLUMN(G17),4)=1)*G17:DB17) -> 1726247 | DH17: =SUMPRODUCT((MOD(COLUMN(G17:DB17)-COLUMN(H17),4)=2)*G17:DB17) -> 1985184 | DI17: 1 | DJ17: =DI17*DD17 -> 1726247 | DK17: =DJ17-DG17 -> 0
A18: EGEC - NIS2 | B18: MLTX-01-099 | C18: 1 | D18: Updated concept masterplan & Infrastructure designs for Tabouk ind. City | E18: TAB-01-009 | F18: 4360270 | G18: 45496 | H18: ='EGEC - NIS2'!M17 -> 1395290.5 | I18: =H18*15% -> 209293.57 | J18: =H18+I18 -> 1604584.1 | K18: 45532 | L18: ='EGEC - NIS2'!O17 -> 1874916.4 | M18: =L18*15% -> 281237.46 | N18: =L18+M18 -> 2156153.8 | W18: 45626 | X18: ='EGEC - NIS2'!Q17 -> 872049.61 | Y18: =X18*15% -> 130807.44 | Z18: =X18+Y18 -> 1002857.1 | AA18: 45651 | AB18: ='EGEC - NIS2'!S17 -> 218013.5 | AC18: =AB18*15% -> 32702.025 | AD18: =AB18+AC18 -> 250715.52 | DD18: =F18 -> 4360270 | DE18: =DD18*15% -> 654040.5 | DF18: =DD18+DE18 -> 5014310.5 | DG18: =SUMPRODUCT((MOD(COLUMN(G18:DB18)-COLUMN(G18),4)=1)*G18:DB18) -> 4360270 | DH18: =SUMPRODUCT((MOD(COLUMN(G18:DB18)-COLUMN(H18),4)=2)*G18:DB18) -> 5014310.5 | DI18: 1 | DJ18: =DI18*DD18 -> 4360270 | DK18: =DJ18-DG18 -> 5.0002709e-06
A19: EGEC - NIS2 | B19: MLTX-01-099 | C19: 2 | D19: Project support services (6 months) (Masterplan) | F19: 744150 | K19: 45532 | L19: ='EGEC - NIS2'!O32 -> 372075 | M19: =L19*15% -> 55811.25 | N19: =L19+M19 -> 427886.25 | S19: 45596 | T19: ='EGEC - NIS2'!Q32 -> 372075 | U19: =T19*15% -> 55811.25 | V19: =T19+U19 -> 427886.25 | DD19: =F19 -> 744150 | DE19: =DD19*15% -> 111622.5 | DF19: =DD19+DE19 -> 855772.5 | DG19: =SUMPRODUCT((MOD(COLUMN(G19:DB19)-COLUMN(G19),4)=1)*G19:DB19) -> 744150 | DH19: =SUMPRODUCT((MOD(COLUMN(G19:DB19)-COLUMN(H19),4)=2)*G19:DB19) -> 855772.5 | DI19: 1 | DJ19: =DI19*DD19 -> 744150 | DK19: =DJ19-DG19 -> 0
A20: EGEC - NIS2 | B20: MLTX-01-099 | C20: 3 | D20: Project support services (6 months) (VRO) | F20: 744150 | AE20: 45688 | AF20: ='EGEC - NIS2'!U32 -> 372075 | AG20: =AF20*15% -> 55811.25 | AH20: =AF20+AG20 -> 427886.25 | AU20: 45807 | AV20: ='EGEC - NIS2'!W32 -> 372075 | AW20: =AV20*15% -> 55811.25 | AX20: =AV20+AW20 -> 427886.25 | DD20: =F20 -> 744150 | DE20: =DD20*15% -> 111622.5 | DF20: =DD20+DE20 -> 855772.5 | DG20: =SUMPRODUCT((MOD(COLUMN(G20:DB20)-COLUMN(G20),4)=1)*G20:DB20) -> 744150 | DH20: =SUMPRODUCT((MOD(COLUMN(G20:DB20)-COLUMN(H20),4)=2)*G20:DB20) -> 855772.5 | DI20: 1 | DJ20: =DI20*DD20 -> 744150 | DK20: =DJ20-DG20 -> 0
A21: EGEC - NIS2 | B21: MLTX-01-099 | C21: 4 | D21: Testing and evaluating concrete structure | F21: 153002 | K21: 45532 | L21: ='EGEC - NIS2'!O47 -> 107101.54 | M21: =L21*15% -> 16065.231 | N21: =L21+M21 -> 123166.77 | O21: 45586 | P21: ='EGEC - NIS2'!Q47 -> 45900.66 | Q21: =P21*15% -> 6885.099 | R21: =P21+Q21 -> 52785.759 | DD21: =F21 -> 153002 | DE21: =DD21*15% -> 22950.3 | DF21: =DD21+DE21 -> 175952.3 | DG21: =SUMPRODUCT((MOD(COLUMN(G21:DB21)-COLUMN(G21),4)=1)*G21:DB21) -> 153002.2 | DH21: =SUMPRODUCT((MOD(COLUMN(G21:DB21)-COLUMN(H21),4)=2)*G21:DB21) -> 175952.53 | DI21: 1 | DJ21: =DI21*DD21 -> 153002 | DK21: =DJ21-DG21 -> -0.2
A22: EGEC - NIS2 | B22: MLTX-01-099 | C22: 5 | D22: Preliminary designs for the expansion of the industrial city in riyadh | F22: 156177 | O22: 45586 | P22: ='EGEC - NIS2'!Q64 -> 109323.9 | Q22: =P22*15% -> 16398.585 | R22: =P22+Q22 -> 125722.48 | W22: 45626 | X22: 46853.1 | Y22: =X22*15% -> 7027.965 | Z22: =X22+Y22 -> 53881.065 | DD22: =F22 -> 156177 | DE22: =DD22*15% -> 23426.55 | DF22: =DD22+DE22 -> 179603.55 | DG22: =SUMPRODUCT((MOD(COLUMN(G22:DB22)-COLUMN(G22),4)=1)*G22:DB22) -> 156177 | DH22: =SUMPRODUCT((MOD(COLUMN(G22:DB22)-COLUMN(H22),4)=2)*G22:DB22) -> 179603.55 | DI22: 1 | DJ22: =DI22*DD22 -> 156177 | DK22: =DJ22-DG22 -> 0
A23: EGEC - NIS2 | B23: MLTX-01-099 | C23: 6 | D23: Incubators in Al-Qassim Oasis | E23: QSM3-01-014 | F23: 1656100 | W23: 45626 | X23: 248415 | Y23: =X23*15% -> 37262.25 | Z23: =X23+Y23 -> 285677.25 | AA23: 45651 | AB23: ='EGEC - NIS2'!M82 -> 828050 | AC23: =AB23*15% -> 124207.5 | AD23: =AB23+AC23 -> 952257.5 | AE23: 45688 | AF23: ='EGEC - NIS2'!O82 -> 579635 | AG23: =AF23*15% -> 86945.25 | AH23: =AF23+AG23 -> 666580.25 | DD23: =F23 -> 1656100 | DE23: =DD23*15% -> 248415 | DF23: =DD23+DE23 -> 1904515 | DG23: =SUMPRODUCT((MOD(COLUMN(G23:DB23)-COLUMN(G23),4)=1)*G23:DB23) -> 1656100 | DH23: =SUMPRODUCT((MOD(COLUMN(G23:DB23)-COLUMN(H23),4)=2)*G23:DB23) -> 1904515 | DI23: 1 | DJ23: =DI23*DD23 -> 1656100 | DK23: =DJ23-DG23 -> 0
A24: EGEC - NIS2 | B24: MLTX-01-099 | C24: 7 | D24: Site development and infrastructure design works for expansion in Jeddah 1 | E24: JDH1-01-021 | F24: 2560090 | AE24: 45688 | AF24: ='EGEC - NIS2'!O101 -> 384013.5 | AG24: =AF24*15% -> 57602.025 | AH24: =AF24+AG24 -> 441615.53 | AM24: 45760 | AN24: ='EGEC - NIS2'!S101 -> 384013.5 | AO24: =AN24*15% -> 57602.025 | AP24: =AN24+AO24 -> 441615.53 | AQ24: 45777 | AR24: ='EGEC - NIS2'!U101 -> 640022.5 | AS24: =AR24*15% -> 96003.375 | AT24: =AR24+AS24 -> 736025.88 | AU24: 45807 | AV24: ='EGEC - NIS2'!W101 -> 896032 | AW24: =AV24*15% -> 134404.8 | AX24: =AV24+AW24 -> 1030436.8 | AY24: 45865 | AZ24: ='EGEC - NIS2'!Y101 -> 256008.5 | BA24: =AZ24*15% -> 38401.275 | BB24: =AZ24+BA24 -> 294409.78 | DD24: =F24 -> 2560090 | DE24: =DD24*15% -> 384013.5 | DF24: =DD24+DE24 -> 2944103.5 | DG24: =SUMPRODUCT((MOD(COLUMN(G24:DB24)-COLUMN(G24),4)=1)*G24:DB24) -> 2560090 | DH24: =SUMPRODUCT((MOD(COLUMN(G24:DB24)-COLUMN(H24),4)=2)*G24:DB24) -> 2944103.5 | DI24: 1 | DJ24: =DI24*DD24 -> 2560090 | DK24: =DJ24-DG24 -> 0
A25: EGEC - NIS2 | B25: MLTX-01-099 | C25: 8 | D25: Detailed design of connection road (Fly Over) in Dammam 2 | E25: DAM2-01-033 | F25: 2310000 | AM25: 45760 | AN25: ='EGEC - NIS2'!S165 -> 693000 | AO25: =AN25*15% -> 103950 | AP25: =AN25+AO25 -> 796950 | CA25: 46140 | CB25: 577500 | CC25: =Currentinvoices[[#This Row],[Invoice '# 19 amount]]*15% -> 86625 | CD25: =Currentinvoices[[#This Row],[Invoice '# 19 vat]]+Currentinvoices[[#This Row],[Invoice '# 19 amount]] -> 664125 | CE25: 46190 | CF25: 808500 | CG25: =Currentinvoices[[#This Row],[Invoice '# 20 amount]]*15% -> 121275 | CH25: =Currentinvoices[[#This Row],[Invoice '# 20 amount]]+Currentinvoices[[#This Row],[Invoice '# 20 vat]] -> 929775 | DD25: =F25 -> 2310000 | DE25: =DD25*15% -> 346500 | DF25: =DD25+DE25 -> 2656500 | DG25: =SUMPRODUCT((MOD(COLUMN(G25:DB25)-COLUMN(G25),4)=1)*G25:DB25) -> 2079000 | DH25: =SUMPRODUCT((MOD(COLUMN(G25:DB25)-COLUMN(H25),4)=2)*G25:DB25) -> 2390850 | DI25: 1 | DJ25: =DI25*DD25 -> 2310000 | DK25: =DJ25-DG25 -> 231000
A26: EGEC - NIS2 | B26: MLTX-01-099 | C26: 9 | D26: Labour camp masterplan and infrastructure development in AlKharj | E26: KHJ-01-025 | F26: 350000 | AI26: 45718 | AJ26: ='EGEC - NIS2'!Q124 -> 175000 | AK26: =AJ26*15% -> 26250 | AL26: =AJ26+AK26 -> 201250 | AM26: 45760 | AN26: ='EGEC - NIS2'!S124 -> 175000 | AO26: =AN26*15% -> 26250 | AP26: =AN26+AO26 -> 201250 | DD26: =F26 -> 350000 | DE26: =DD26*15% -> 52500 | DF26: =DD26+DE26 -> 402500 | DG26: =SUMPRODUCT((MOD(COLUMN(G26:DB26)-COLUMN(G26),4)=1)*G26:DB26) -> 350000 | DH26: =SUMPRODUCT((MOD(COLUMN(G26:DB26)-COLUMN(H26),4)=2)*G26:DB26) -> 402500 | DI26: 1 | DJ26: =DI26*DD26 -> 350000 | DK26: =DJ26-DG26 -> 0
A27: EGEC - NIS2 | B27: MLTX-01-099 | C27: 10 | D27: Potable water pipeline supply and connection to alkharj 1st ind. City | E27: KHJ-01-026 | F27: 534490 | AM27: 45760 | AN27: ='EGEC - NIS2'!S146 -> 210000 | AO27: =AN27*15% -> 31500 | AP27: =AN27+AO27 -> 241500 | BC27: 45907 | BD27: ='EGEC - NIS2'!U146 -> 175000.64 | BE27: =BD27*15% -> 26250.096 | BF27: =BD27+BE27 -> 201250.74 | BO27: 45994 | BP27: ='EGEC - NIS2'!W146 -> 140000 | BQ27: ='Invoices (2)'!$BP27*15% -> 21000 | BR27: ='Invoices (2)'!$BQ27+'Invoices (2)'!$BP27 -> 161000 | BS27: 46014 | BT27: 9490 | BU27: =Currentinvoices[[#This Row],[Invoice '# 17 amount]]*15% -> 1423.5 | BV27: =Currentinvoices[[#This Row],[Invoice '# 17 amount]]+Currentinvoices[[#This Row],[Invoice '# 17 vat]] -> 10913.5 | DD27: =F27 -> 534490 | DE27: =DD27*15% -> 80173.5 | DF27: =DD27+DE27 -> 614663.5 | DG27: =SUMPRODUCT((MOD(COLUMN(G27:DB27)-COLUMN(G27),4)=1)*G27:DB27) -> 534490.64 | DH27: =SUMPRODUCT((MOD(COLUMN(G27:DB27)-COLUMN(H27),4)=2)*G27:DB27) -> 614664.24 | DI27: 1 | DJ27: =DI27*DD27 -> 534490 | DK27: =DJ27-DG27 -> -0.64
A28: EGEC - NIS2 | B28: MLTX-01-099 | C28: 11 | D28: Study design RBFs 900 & 450m2 SFDA requirements | F28: 170000 | AM28: 45760 | AN28: ='EGEC - NIS2'!S183 -> 85000 | AO28: =AN28*15% -> 12750 | AP28: =AN28+AO28 -> 97750 | BG28: 45929 | BH28: ='EGEC - NIS2'!W183 -> 85000 | BI28: ='Invoices (2)'!$BH28*15% -> 12750 | BJ28: ='Invoices (2)'!$BH28+'Invoices (2)'!$BI28 -> 97750 | DD28: =F28 -> 170000 | DE28: =DD28*15% -> 25500 | DF28: =DD28+DE28 -> 195500 | DG28: =SUMPRODUCT((MOD(COLUMN(G28:DB28)-COLUMN(G28),4)=1)*G28:DB28) -> 170000 | DH28: =SUMPRODUCT((MOD(COLUMN(G28:DB28)-COLUMN(H28),4)=2)*G28:DB28) -> 195500 | DI28: 1 | DJ28: =DI28*DD28 -> 170000 | DK28: =DJ28-DG28 -> 0
A29: EGEC - NIS2 | B29: MLTX-01-099 | C29: 12 | D29: Improving the entrances and exit points for Jeddah 1 | E29: JDH1-01-028 | F29: 1590000 | BK29: 45956 | BL29: ='EGEC - NIS2'!M247 -> 794999.1 | BM29: ='Invoices (2)'!$BL29*15% -> 119249.87 | BN29: ='Invoices (2)'!$BL29+'Invoices (2)'!$BM29 -> 914248.97 | BS29: 46014 | BT29: 556500 | BU29: =Currentinvoices[[#This Row],[Invoice '# 17 amount]]*15% -> 83475 | BV29: =Currentinvoices[[#This Row],[Invoice '# 17 amount]]+Currentinvoices[[#This Row],[Invoice '# 17 vat]] -> 639975 | CE29: 46190 | CF29: 119250 | CG29: =Currentinvoices[[#This Row],[Invoice '# 20 amount]]*15% -> 17887.5 | CH29: =Currentinvoices[[#This Row],[Invoice '# 20 amount]]+Currentinvoices[[#This Row],[Invoice '# 20 vat]] -> 137137.5 | DD29: =F29 -> 1590000 | DE29: =DD29*15% -> 238500 | DF29: =DD29+DE29 -> 1828500 | DG29: =SUMPRODUCT((MOD(COLUMN(G29:DB29)-COLUMN(G29),4)=1)*G29:DB29) -> 1470749.1 | DH29: =SUMPRODUCT((MOD(COLUMN(G29:DB29)-COLUMN(H29),4)=2)*G29:DB29) -> 1691361.5 | DI29: 1 | DJ29: =DI29*DD29 -> 1590000 | DK29: =DJ29-DG29 -> 119250.9
A30: EGEC - NIS2 | B30: MLTX-01-099 | C30: 13 | D30: Hydrology study for Jeddah 2 | E30: JDH2-01-028 | F30: 110500 | BK30: 45956 | BL30: ='EGEC - NIS2'!M232 -> 44199.17 | BM30: ='Invoices (2)'!$BL30*15% -> 6629.8755 | BN30: ='Invoices (2)'!$BL30+'Invoices (2)'!$BM30 -> 50829.046 | BW30: 46056 | BX30: 66300 | BY30: =Currentinvoices[[#This Row],[Invoice '# 18 amount]]*15% -> 9945 | BZ30: =Currentinvoices[[#This Row],[Invoice '# 18 vat]]+Currentinvoices[[#This Row],[Invoice '# 18 amount]] -> 76245 | DD30: =F30 -> 110500 | DE30: =DD30*15% -> 16575 | DF30: =DD30+DE30 -> 127075 | DG30: =SUMPRODUCT((MOD(COLUMN(G30:DB30)-COLUMN(G30),4)=1)*G30:DB30) -> 110499.17 | DH30: =SUMPRODUCT((MOD(COLUMN(G30:DB30)-COLUMN(H30),4)=2)*G30:DB30) -> 127074.05 | DI30: 1 | DJ30: =DI30*DD30 -> 110500 | DK30: =DJ30-DG30 -> 0.83
A31: EGEC - NIS2 | B31: MLTX-01-099 | C31: 14 | D31: Jenadriyadh Business Incubators | E31: JNDT-01-002 | F31: 500000 | BO31: 45994 | BP31: ='EGEC - NIS2'!M262 -> 100000 | BQ31: ='Invoices (2)'!$BP31*15% -> 15000 | BR31: ='Invoices (2)'!$BQ31+'Invoices (2)'!$BP31 -> 115000 | BS31: 46014 | BT31: 225000 | BU31: =Currentinvoices[[#This Row],[Invoice '# 17 amount]]*15% -> 33750 | BV31: =Currentinvoices[[#This Row],[Invoice '# 17 amount]]+Currentinvoices[[#This Row],[Invoice '# 17 vat]] -> 258750 | BW31: 46056 | BX31: 100000 | BY31: =Currentinvoices[[#This Row],[Invoice '# 18 amount]]*15% -> 15000 | BZ31: =Currentinvoices[[#This Row],[Invoice '# 18 vat]]+Currentinvoices[[#This Row],[Invoice '# 18 amount]] -> 115000 | CA31: 46140 | CB31: 75000 | CC31: =Currentinvoices[[#This Row],[Invoice '# 19 amount]]*15% -> 11250 | CD31: =Currentinvoices[[#This Row],[Invoice '# 19 vat]]+Currentinvoices[[#This Row],[Invoice '# 19 amount]] -> 86250 | DD31: =F31 -> 500000 | DE31: =DD31*15% -> 75000 | DF31: =DD31+DE31 -> 575000 | DG31: =SUMPRODUCT((MOD(COLUMN(G31:DB31)-COLUMN(G31),4)=1)*G31:DB31) -> 500000 | DH31: =SUMPRODUCT((MOD(COLUMN(G31:DB31)-COLUMN(H31),4)=2)*G31:DB31) -> 575000 | DI31: 1 | DJ31: =DI31*DD31 -> 500000 | DK31: =DJ31-DG31 -> 0
A32: EGEC - NIS2 | B32: MLTX-01-099 | C32: 15 | D32: Project support services 3 | F32: 1798340 | BC32: 45907 | BD32: ='EGEC - NIS2'!M202 -> 449585 | BE32: =BD32*15% -> 67437.75 | BF32: =BD32+BE32 -> 517022.75 | BG32: 45929 | BH32: ='EGEC - NIS2'!O202 -> 449585 | BI32: ='Invoices (2)'!$BH32*15% -> 67437.75 | BJ32: ='Invoices (2)'!$BH32+'Invoices (2)'!$BI32 -> 517022.75 | BS32: 46014 | BT32: 449585 | BU32: =Currentinvoices[[#This Row],[Invoice '# 17 amount]]*15% -> 67437.75 | BV32: =Currentinvoices[[#This Row],[Invoice '# 17 amount]]+Currentinvoices[[#This Row],[Invoice '# 17 vat]] -> 517022.75 | BW32: 46056 | BX32: 449585 | BY32: =Currentinvoices[[#This Row],[Invoice '# 18 amount]]*15% -> 67437.75 | BZ32: =Currentinvoices[[#This Row],[Invoice '# 18 vat]]+Currentinvoices[[#This Row],[Invoice '# 18 amount]] -> 517022.75 | DD32: ='Invoices (2)'!$F32 -> 1798340 | DE32: =DD32*15% -> 269751 | DF32: =DD32+DE32 -> 2068091 | DG32: =SUMPRODUCT((MOD(COLUMN(G32:DB32)-COLUMN(G32),4)=1)*G32:DB32) -> 1798340 | DH32: =SUMPRODUCT((MOD(COLUMN(G32:DB32)-COLUMN(H32),4)=2)*G32:DB32) -> 2068091 | DI32: 1 | DJ32: =DI32*DD32 -> 1798340 | DK32: =DJ32-DG32 -> 0
A33: EGEC - NIS2 | B33: MLTX-01-099 | C33: 16 | D33: Adaptation and Design of an Administrative Building Humanization in Riyadh 2 | E33: RDH2-01-031 | F33: 590000 | BG33: 45929 | BH33: ='EGEC - NIS2'!M217 -> 471999.23 | BI33: ='Invoices (2)'!$BH33*15% -> 70799.885 | BJ33: ='Invoices (2)'!$BH33+'Invoices (2)'!$BI33 -> 542799.11 | BO33: 45994 | BP33: ='EGEC - NIS2'!O217 -> 59000 | BQ33: ='Invoices (2)'!$BP33*15% -> 8850 | BR33: ='Invoices (2)'!$BQ33+'Invoices (2)'!$BP33 -> 67850 | BW33: 46056 | BX33: 59000 | BY33: =Currentinvoices[[#This Row],[Invoice '# 18 amount]]*15% -> 8850 | BZ33: =Currentinvoices[[#This Row],[Invoice '# 18 vat]]+Currentinvoices[[#This Row],[Invoice '# 18 amount]] -> 67850 | DD33: ='Invoices (2)'!$F33 -> 590000 | DE33: =DD33*15% -> 88500 | DF33: =DD33+DE33 -> 678500 | DG33: =SUMPRODUCT((MOD(COLUMN(G33:DB33)-COLUMN(G33),4)=1)*G33:DB33) -> 589999.23 | DH33: =SUMPRODUCT((MOD(COLUMN(G33:DB33)-COLUMN(H33),4)=2)*G33:DB33) -> 678499.11 | DI33: 0.95 | DJ33: =DI33*DD33 -> 560500 | DK33: =DJ33-DG33 -> -29499.23
A34: EGEC - NIS2 | B34: MLTX-01-099 | C34: 17 | D34: Ddevelopment The walkway In residential area Jeddah1 | F34: 170000 | CA34: 46140 | CB34: 119000 | CC34: =Currentinvoices[[#This Row],[Invoice '# 19 amount]]*15% -> 17850 | CD34: =Currentinvoices[[#This Row],[Invoice '# 19 vat]]+Currentinvoices[[#This Row],[Invoice '# 19 amount]] -> 136850 | CE34: 46190 | CF34: ='EGEC - NIS2'!O291 -> 51000.21 | CG34: =Currentinvoices[[#This Row],[Invoice '# 20 amount]]*15% -> 7650.0315 | CH34: =Currentinvoices[[#This Row],[Invoice '# 20 amount]]+Currentinvoices[[#This Row],[Invoice '# 20 vat]] -> 58650.241 | DD34: =Currentinvoices[[#This Row],[Task Value]] -> 170000 | DE34: =DD34*15% -> 25500 | DF34: =DD34+DE34 -> 195500 | DG34: =SUMPRODUCT((MOD(COLUMN(G34:DB34)-COLUMN(G34),4)=1)*G34:DB34) -> 170000.21 | DH34: =SUMPRODUCT((MOD(COLUMN(G34:DB34)-COLUMN(H34),4)=2)*G34:DB34) -> 195500.24 | DI34: 1 | DJ34: =DI34*DD34 -> 170000 | DK34: =DJ34-DG34 -> -0.21
A35: ENGICON | B35: RDH4-00-001 | C35: 1 | D35: Riyadh 4 Masterplan and Infrastructure concept design | F35: 27837620 | G35: 45480 | H35: =ENGICON!F45 -> 2361050.1 | I35: =H35*15% -> 354157.52 | J35: =H35+I35 -> 2715207.6 | K35: 45511 | L35: =ENGICON!H45 -> 3157746.7 | M35: =L35*15% -> 473662 | N35: =L35+M35 -> 3631408.6 | O35: 45535 | P35: =ENGICON!J45 -> 3983985.9 | Q35: =P35*15% -> 597597.89 | R35: =P35+Q35 -> 4581583.8 | S35: 45567 | T35: =ENGICON!L45 -> 3449998.3 | U35: =T35*15% -> 517499.74 | V35: =T35+U35 -> 3967498 | W35: 45636 | X35: =ENGICON!N45 -> 1820099.7 | Y35: =X35*15% -> 273014.96 | Z35: =X35+Y35 -> 2093114.7 | AA35: 45685 | AB35: =ENGICON!P45 -> 1000000 | AC35: =AB35*15% -> 150000 | AD35: =AB35+AC35 -> 1150000 | AE35: 45720 | AF35: =ENGICON!R45 -> 2695839.6 | AG35: =AF35*15% -> 404375.94 | AH35: =AF35+AG35 -> 3100215.6 | AI35: 45767 | AJ35: =ENGICON!T45 -> 2223402.9 | AK35: =AJ35*15% -> 333510.43 | AL35: =AJ35+AK35 -> 2556913.3 | AM35: 45789 | AN35: 1742432.4 | AO35: =AN35*15% -> 261364.86 | AP35: =AN35+AO35 -> 2003797.3 | AQ35: 45809 | AR35: 2619302.4 | AS35: =AR35*15% -> 392895.37 | AT35: =AR35+AS35 -> 3012197.8 | DD35: =F35 -> 27837620 | DE35: =DD35*15% -> 4175643 | DF35: =DD35+DE35 -> 32013263 | DG35: =SUMPRODUCT((MOD(COLUMN(G35:DB35)-COLUMN(G35),4)=1)*G35:DB35) -> 25053858 | DH35: =SUMPRODUCT((MOD(COLUMN(G35:DB35)-COLUMN(H35),4)=2)*G35:DB35) -> 28811937 | DI35: 1 | DJ35: =DI35*DD35 -> 27837620 | DK35: =DJ35-DG35 -> 2783762
A36: ENGICON | B36: RDH4-00-001 | DG36: =SUMPRODUCT((MOD(COLUMN(G36:DB36)-COLUMN(G36),4)=1)*G36:DB36) -> 0 | DH36: =SUMPRODUCT((MOD(COLUMN(G36:DB36)-COLUMN(H36),4)=2)*G36:DB36) -> 0
A37: EGEC - WAS | B37: WAS1-01-039 | C37: 1 | D37: Site development and buildings design for labour community area in WAS industrial city | E37: WAS1-01-035 | F37: 4421850 | G37: 45354 | H37: ='EGEC - WAS'!M17 -> 1726555 | I37: =H37*15% -> 258983.25 | J37: =H37+I37 -> 1985538.2 | O37: 45777 | P37: ='EGEC - WAS'!Q17 -> 1641704.7 | Q37: =P37*15% -> 246255.7 | R37: =P37+Q37 -> 1887960.4 | S37: 45807 | T37: ='EGEC - WAS'!S17 -> 611379 | U37: =T37*15% -> 91706.85 | V37: =T37+U37 -> 703085.85 | W37: 45865 | X37: ='EGEC - WAS'!U17 -> 221091 | Y37: =X37*15% -> 33163.65 | Z37: =X37+Y37 -> 254254.65 | AA37: 45901 | AB37: ='EGEC - WAS'!W17 -> 221120.33 | AC37: ='Invoices (2)'!$AB37*15% -> 33168.05 | AD37: ='Invoices (2)'!$AB37+'Invoices (2)'!$AC37 -> 254288.38 | DD37: =F37 -> 4421850 | DE37: =DD37*15% -> 663277.5 | DF37: =DD37+DE37 -> 5085127.5 | DG37: =SUMPRODUCT((MOD(COLUMN(G37:DB37)-COLUMN(G37),4)=1)*G37:DB37) -> 4421850 | DH37: =SUMPRODUCT((MOD(COLUMN(G37:DB37)-COLUMN(H37),4)=2)*G37:DB37) -> 5085127.5 | DI37: 1 | DJ37: =DI37*DD37 -> 4421850 | DK37: =DJ37-DG37 -> -0.0099999998
A38: EGEC - WAS | B38: WAS1-01-039 | C38: 2 | D38: Design commercial area with fuel station in Waad AlShamal | E38: WAS-01-034 | F38: 650000 | K38: 45395 | L38: ='EGEC - WAS'!O36 -> 195000 | M38: =L38*15% -> 29250 | N38: =L38+M38 -> 224250 | O38: 45777 | P38: ='EGEC - WAS'!Q36 -> 227500 | Q38: =P38*15% -> 34125 | R38: =P38+Q38 -> 261625 | S38: 45807 | T38: ='EGEC - WAS'!S36 -> 227500 | U38: =T38*15% -> 34125 | V38: =T38+U38 -> 261625 | DD38: =F38 -> 650000 | DE38: =DD38*15% -> 97500 | DF38: =DD38+DE38 -> 747500 | DG38: =SUMPRODUCT((MOD(COLUMN(G38:DB38)-COLUMN(G38),4)=1)*G38:DB38) -> 650000 | DH38: =SUMPRODUCT((MOD(COLUMN(G38:DB38)-COLUMN(H38),4)=2)*G38:DB38) -> 747500 | DI38: 1 | DJ38: =DI38*DD38 -> 650000 | DK38: =DJ38-DG38 -> 0
A39: EGEC - WAS | B39: WAS1-01-039 | C39: 4 | D39: Development of labour camps in: DAM03, NJR, MKH2, JDH2, SUD, ASR1 | E39: MLTX-01-119 | F39: 1150000 | W39: 45865 | X39: 115000 | Y39: =X39*15% -> 17250 | Z39: =X39+Y39 -> 132250 | AE39: 45917 | AF39: 460000 | AG39: ='Invoices (2)'!$AF39*15% -> 69000 | AH39: ='Invoices (2)'!$AF39+'Invoices (2)'!$AG39 -> 529000 | AI39: 45956 | AJ39: 575000 | AK39: ='Invoices (2)'!$AJ39*15% -> 86250 | AL39: ='Invoices (2)'!$AJ39+'Invoices (2)'!$AK39 -> 661250 | DD39: =F39 -> 1150000 | DE39: =DD39*15% -> 172500 | DF39: =DD39+DE39 -> 1322500 | DG39: =SUMPRODUCT((MOD(COLUMN(G39:DB39)-COLUMN(G39),4)=1)*G39:DB39) -> 1150000 | DH39: =SUMPRODUCT((MOD(COLUMN(G39:DB39)-COLUMN(H39),4)=2)*G39:DB39) -> 1322500 | DI39: 1 | DJ39: =DI39*DD39 -> 1150000 | DK39: =DJ39-DG39 -> 0
A40: EGEC - WAS | B40: WAS1-01-039 | C40: 4 | D40: Project support services 4 | F40: 853820 | AM40: 45994 | AN40: ='EGEC - WAS'!M65 -> 284606.76 | AO40: ='Invoices (2)'!$AN40*15% -> 42691.014 | AP40: ='Invoices (2)'!$AN40+'Invoices (2)'!$AO40 -> 327297.77 | AQ40: 46056 | AR40: ='EGEC - WAS'!O65 -> 355759.13 | AS40: =Currentinvoices[[#This Row],[Invoice '# 10 amount]]*15% -> 53363.87 | AT40: =Currentinvoices[[#This Row],[Invoice '# 10 amount]]+Currentinvoices[[#This Row],[Invoice '# 10 vat]] -> 409123 | AU40: 46205 | AV40: 213455 | AW40: =Currentinvoices[[#This Row],[Invoice '# 11 amount]]*15% -> 32018.25 | AX40: =Currentinvoices[[#This Row],[Invoice '# 11 vat]]+Currentinvoices[[#This Row],[Invoice '# 11 amount]] -> 245473.25 | DD40: =Currentinvoices[[#This Row],[Task Value]] -> 853820 | DE40: =DD40*15% -> 128073 | DF40: =DD40+DE40 -> 981893 | DG40: =SUMPRODUCT((MOD(COLUMN(G40:DB40)-COLUMN(G40),4)=1)*G40:DB40) -> 853820.89 | DH40: =SUMPRODUCT((MOD(COLUMN(G40:DB40)-COLUMN(H40),4)=2)*G40:DB40) -> 981894.02 | DI40: 1 | DJ40: =DI40*DD40 -> 853820 | DK40: =DJ40-DG40 -> -0.89
A41: ENGICON - RDH4 | B41: RDH4-01-002 | C41: 1 | D41: Design work for entrance and facilities for Riyadh 4 | F41: 7025000 | G41: 45684 | H41: ='ENGICON-RDH4'!F11 -> 1999999.9 | I41: =H41*15% -> 299999.98 | J41: =H41+I41 -> 2299999.8 | K41: 45839 | L41: ='ENGICON-RDH4'!H11 -> 2350000 | M41: =L41*15% -> 352500 | N41: =L41+M41 -> 2702500 | O41: 45848 | P41: ='ENGICON-RDH4'!J11 -> 2675000 | Q41: =P41*15% -> 401250 | R41: =P41+Q41 -> 3076250 | DD41: =F41 -> 7025000 | DE41: =DD41*15% -> 1053750 | DF41: =DD41+DE41 -> 8078750 | DG41: =SUMPRODUCT((MOD(COLUMN(G41:DB41)-COLUMN(G41),4)=1)*G41:DB41) -> 7024999.8 | DH41: =SUMPRODUCT((MOD(COLUMN(G41:DB41)-COLUMN(H41),4)=2)*G41:DB41) -> 8078749.8 | DI41: 1 | DJ41: =DI41*DD41 -> 7025000 | DK41: =DJ41-DG41 -> 0.15
...

Sheet Sheet4
A1: Framework name | B1: Framework ID | C1: Framework Total amount | D1: Framework Status | E1: Project Name | F1: Project status | G1: Project ID | H1: Project Total amount
A2: Dorsch food | B2: MLTX-01-085 | C2: 19993600 | D2: Closed | E2: Jeddah 2 - Food Cluster - RBF 450 & 900 m2 | F2: Closed | G2: JDH2-01-016 | H2: 877779
A3: Dorsch food | B3: MLTX-01-085 | C3: 19993600 | D3: Closed | E3: Jeddah Food Cluster - Masterplan Update & Lands Selection at Jeddah 2nd & 3rd Ind. Cities | F3: Closed | G3: MLTX-01-093 | H3: 1403611
A4: Dorsch food | B4: MLTX-01-085 | C4: 19993600 | D4: Closed | E4: Jeddah 3 - Design of Shared Dry & Cold Storage Warehouses in Jeddah 3 Ind. City | F4: Closed | G4: JDH3-01-021 | H4: 2999654
A5: Dorsch food | B5: MLTX-01-085 | C5: 19993600 | D5: Closed | E5: Master planning a logistic area in Dammam 2 | F5: Closed | G5: DAM2-01-026 | H5: 4125000
A6: Dorsch food | B6: MLTX-01-085 | C6: 19993600 | D6: Closed | E6: Hydrology Study for preventing Jeddah 4th Industrial City from floods and stormwater | F6: Closed | G6: JDH4-01-040 | H6: 404258
A7: Dorsch food | B7: MLTX-01-085 | C7: 19993600 | D7: Closed | E7: Completing the infrastructure networks and residential neighborhood in the 2nd industrial city in Dammam | F7: Closed | G7: DAM2-02-027 | H7: 6968306
A8: Dorsch food | B8: MLTX-01-085 | C8: 19993600 | D8: Closed | E8: Reviewing the masterplan for alkhrj nd. City | F8: Closed | H8: 174000
A9: Dorsch food | B9: MLTX-01-085 | C9: 19993600 | D9: Closed | E9: Detail MPL and infra Design for the multi-use area in Dammam2 | F9: Closed | G9: DAM2-01-029 | H9: 836000
A10: Dorsch food | B10: MLTX-01-085 | C10: 19993600 | D10: Closed | E10: Design shared services center - Food cluster | F10: Closed | G10: JDH2-01-023 | H10: 1505768
A11: Dorsch food | B11: MLTX-01-085 | C11: 19993600 | D11: Closed | E11: الدراسه القيميه لمشاريع المصانع الجاهزة | F11: Closed | H11: 264505
A12: SYSTRA | B12: MLTX-01-102 | C12: 15054089 | D12: ongoing | E12: Masterplan & Infrstructure Detailed Design For Technology Zones (Jenadryah) | F12: Closed | G12: JNDT-01-001 | H12: 6726972
A13: SYSTRA | B13: MLTX-01-102 | C13: 15054089 | D13: ongoing | E13: Masterplan & Infrstructure Detailed Design For Technology Zones (Dammam) | F13: ongoing | G13: DAMT-01-001 | H13: 3300435
A14: SYSTRA | B14: MLTX-01-102 | C14: 15054089 | D14: ongoing | E14: Masterplan & Infrstructure Detailed Design For Technology Zones (Dhahran) | F14: ongoing | G14: DHRT-01-001 | H14: 3300435
A15: SYSTRA | B15: MLTX-01-102 | C15: 15054089 | D15: ongoing | E15: Technical review and transport planning expertise support for Riyadh Industrial cities 1 & 4 | F15: Closed | G15: MLTX-01-111 | H15: 1726247
A16: EGEC - NIS2 | B16: MLTX-01-099 | C16: 19979840 | D16: ongoing | E16: Updated concept masterplan & Infrastructure designs for Tabouk ind. City | F16: Closed | G16: TAB-01-009 | H16: 4360270
A17: EGEC - NIS2 | B17: MLTX-01-099 | C17: 19979840 | D17: ongoing | E17: Project support services (6 months) (Masterplan) | F17: Closed | H17: 744150
A18: EGEC - NIS2 | B18: MLTX-01-099 | C18: 19979840 | D18: ongoing | E18: Project support services (6 months) (VRO) | F18: Closed | H18: 744150
A19: EGEC - NIS2 | B19: MLTX-01-099 | C19: 19979840 | D19: ongoing | E19: Testing and evaluating concrete structure | F19: Closed | H19: 153002
A20: EGEC - NIS2 | B20: MLTX-01-099 | C20: 19979840 | D20: ongoing | E20: Preliminary designs for the expansion of the industrial city in riyadh | H20: 156177
A21: EGEC - NIS2 | B21: MLTX-01-099 | C21: 19979840 | D21: ongoing | E21: Incubators in Al-Qassim Oasis | F21: Closed | G21: QSM3-01-014 | H21: 1656100
A22: EGEC - NIS2 | B22: MLTX-01-099 | C22: 19979840 | D22: ongoing | E22: Site development and infrastructure design works for expansion in Jeddah 1 | F22: Closed | G22: JDH1-01-021 | H22: 2560090
A23: EGEC - NIS2 | B23: MLTX-01-099 | C23: 19979840 | D23: ongoing | E23: Detailed design of connection road (Fly Over) in Dammam 2 | F23: ongoing | G23: DAM2-01-033 | H23: 2310000
A24: EGEC - NIS2 | B24: MLTX-01-099 | C24: 19979840 | D24: ongoing | E24: Labour camp masterplan and infrastructure development in AlKharj | F24: Closed | G24: KHJ-01-025 | H24: 350000
A25: EGEC - NIS2 | B25: MLTX-01-099 | C25: 19979840 | D25: ongoing | E25: Potable water pipeline supply and connection to alkharj 1st ind. City | F25: ongoing | G25: KHJ-01-026 | H25: 534490
A26: EGEC - NIS2 | B26: MLTX-01-099 | C26: 19979840 | D26: ongoing | E26: Study design RBFs 900 & 450m2 SFDA requirements | H26: 170000
A27: EGEC - NIS2 | B27: MLTX-01-099 | C27: 19979840 | D27: ongoing | E27: Improving the entrances and exit points for Jeddah 1 | F27: ongoing | G27: JDH1-01-028 | H27: 1590000
A28: EGEC - NIS2 | B28: MLTX-01-099 | C28: 19979840 | D28: ongoing | E28: Hydrology study for Jeddah 2 | F28: ongoing | H28: 110500
A29: EGEC - NIS2 | B29: MLTX-01-099 | C29: 19979840 | D29: ongoing | E29: Jenadriyadh Business Incubators | F29: ongoing | G29: JNDT-01-002 | H29: 500000
A30: EGEC - NIS2 | B30: MLTX-01-099 | C30: 19979840 | D30: ongoing | E30: Project support services 3 | H30: 1798340
A31: EGEC - NIS2 | B31: MLTX-01-099 | C31: 19979840 | D31: ongoing | E31: Adaptation and Design of an Administrative Building Humanization in Riyadh 2 | F31: ongoing | H31: 590000
A32: ENGICON | B32: RDH4-00-001 | C32: 27837620 | D32: Closed | E32: Riyadh 4 Masterplan and Infrastructure concept design | F32: Closed | G32: RDH4-00-001 | H32: 27837620
A33: EGEC - WAS | B33: WAS1-01-039 | C33: 9799000 | D33: ongoing | E33: Site development and buildings design for labour community area in WAS industrial city | F33: ongoing | G33: WAS-01-035 | H33: 4421850
A34: EGEC - WAS | B34: WAS1-01-039 | C34: 9799000 | D34: ongoing | E34: Design commercial area with fuel station in Waad AlShamal | F34: ongoing | G34: WAS-01-034 | H34: 650000
A35: EGEC - WAS | B35: WAS1-01-039 | C35: 9799000 | D35: ongoing | E35: Development of labour camps in: DAM03, NJR, MKH2, JDH2, SUD, ASR1 | F35: ongoing | G35: MLTX-01-119 | H35: 1150000
A36: EGEC - WAS | B36: WAS1-01-039 | C36: 9799000 | D36: ongoing | E36: Project support services 4 | F36: ongoing | H36: 853820
A37: ENGICON - RDH4 | B37: RDH4-01-002 | C37: 7025000 | D37: Closed | E37: Design work for entrance and facilities for Riyadh 4 | F37: Closed | G37: RDH4-01-002 | H37: 7025000
A38: Dar AlRiyadh 2 | B38: MLTX-01-100 | C38: 59999686 | D38: ongoing | F38: ongoing | G38: MLTX-01-100
A39: ENGICON - Package1 | B39: MLTX-01-098 | C39: 19856000 | D39: ongoing | E39: NIS Design adaptation of RBF 450 , 900 m2 | F39: Closed | H39: 7940002
A40: ENGICON - Package1 | B40: MLTX-01-098 | C40: 19856000 | D40: ongoing | E40: Detailed design of lake park and supply connection for Sudair Industrial City | F40: Closed | G40: SUD1-01-033 | H40: 1658659
...

Sheet EGEC - NIS2
G5: Tabouk | L5: Invoice 1 | N5: Invoice 2 | P5: Invoice 5 | R5: Invoice 6
A6: Description | C6: Total quantity | D6: Remaining quantity | G6: Description | H6: Category | I6: Total Quantity | J6: Remaining quantity | K6: Rate | L6: Quantity | M6: Amount | N6: Quantity2 | O6: Amount3 | P6: Quantity3 | Q6: Amount4 | R6: Quantity25 | S6: Amount36
A7: Lead Engineer/ Discipline Engineer | B7: A1 | C7: 670 | G7: Lead Engineer/ Discipline Engineer | H7: A1 | J7: =Table5[[#This Row],[Total Quantity]]-Table5[[#This Row],[Quantity]]-Table5[[#This Row],[Quantity2]] -> 0 | K7: 465 | M7: =Table5[[#This Row],[Quantity2]]*Table5[[#This Row],[Rate]] -> 0 | O7: =Table5[[#This Row],[Quantity2]]*Table5[[#This Row],[Rate]] -> 0 | Q7: =Table5[[#This Row],[Quantity2]]*Table5[[#This Row],[Rate]] -> 0 | S7: =Table5[[#This Row],[Quantity2]]*Table5[[#This Row],[Rate]] -> 0
A8: Sr. Engineer/ Senior discipline specialist | B8: B1 | C8: 1050 | G8: Sr. Engineer/ Senior discipline specialist | H8: B1 | J8: =Table5[[#This Row],[Total Quantity]]-Table5[[#This Row],[Quantity]]-Table5[[#This Row],[Quantity2]] -> 0 | K8: 390 | M8: =Table5[[#This Row],[Quantity2]]*Table5[[#This Row],[Rate]] -> 0 | O8: =Table5[[#This Row],[Quantity2]]*Table5[[#This Row],[Rate]] -> 0 | Q8: =Table5[[#This Row],[Quantity2]]*Table5[[#This Row],[Rate]] -> 0 | S8: =Table5[[#This Row],[Quantity2]]*Table5[[#This Row],[Rate]] -> 0
A9: Engineer/ Discipline Specialist | B9: C1 | C9: 1810 | G9: Engineer/ Discipline Specialist | H9: C1 | J9: =Table5[[#This Row],[Total Quantity]]-Table5[[#This Row],[Quantity]]-Table5[[#This Row],[Quantity2]] -> 0 | K9: 200 | M9: =Table5[[#This Row],[Quantity2]]*Table5[[#This Row],[Rate]] -> 0 | O9: =Table5[[#This Row],[Quantity2]]*Table5[[#This Row],[Rate]] -> 0 | Q9: =Table5[[#This Row],[Quantity2]]*Table5[[#This Row],[Rate]] -> 0 | S9: =Table5[[#This Row],[Quantity2]]*Table5[[#This Row],[Rate]] -> 0
A10: Draftsman | B10: D1 | C10: 2380 | G10: Draftsman | H10: D1 | J10: =Table5[[#This Row],[Total Quantity]]-Table5[[#This Row],[Quantity]]-Table5[[#This Row],[Quantity2]] -> 0 | K10: 90 | M10: =Table5[[#This Row],[Quantity2]]*Table5[[#This Row],[Rate]] -> 0 | O10: =Table5[[#This Row],[Quantity2]]*Table5[[#This Row],[Rate]] -> 0 | Q10: =Table5[[#This Row],[Quantity2]]*Table5[[#This Row],[Rate]] -> 0 | S10: =Table5[[#This Row],[Quantity2]]*Table5[[#This Row],[Rate]] -> 0
A11: Lead engineer/ discipline expert | B11: A2 | C11: 9040 | D11: =C11-Table5[[#This Row],[Total Quantity]]-I26-I41-I58-I76-I95-I118-I140-I159-I177 -> -1690.27 | G11: Lead engineer/ discipline expert | H11: A2 | I11: 1800 | J11: =Table5[[#This Row],[Total Quantity]]-Table5[[#This Row],[Quantity]]-Table5[[#This Row],[Quantity2]] -> 561.51822 | K11: 275 | L11: 253.5 | M11: =Table5[[#This Row],[Rate]]*Table5[[#This Row],[Quantity]] -> 69712.5 | N11: 984.98178 | O11: =Table5[[#This Row],[Quantity2]]*Table5[[#This Row],[Rate]] -> 270869.99 | P11: 471.51822 | Q11: =Table5[[#This Row],[Rate]]*Table5[[#This Row],[Quantity3]] -> 129667.51 | R11: 90 | S11: =Table5[[#This Row],[Quantity25]]*Table5[[#This Row],[Rate]] -> 24750
A12: Sr. Engineer/ Senior discipline specialist | B12: B2 | C12: 19600 | D12: =C12-Table5[[#This Row],[Total Quantity]]-I27-I42-I59-I77-I96-I119-I141-I160-I178-I272 -> 10753.11 | G12: Sr. Engineer/ Senior discipline specialist | H12: B2 | I12: 3200 | J12: =Table5[[#This Row],[Total Quantity]]-Table5[[#This Row],[Quantity]]-Table5[[#This Row],[Quantity2]] -> 952.45 | K12: 180 | L12: 775.55 | M12: =Table5[[#This Row],[Rate]]*Table5[[#This Row],[Quantity]] -> 139599 | N12: 1472 | O12: =Table5[[#This Row],[Quantity2]]*Table5[[#This Row],[Rate]] -> 264960 | P12: 792.45 | Q12: =Table5[[#This Row],[Rate]]*Table5[[#This Row],[Quantity3]] -> 142641 | R12: 160 | S12: =Table5[[#This Row],[Quantity25]]*Table5[[#This Row],[Rate]] -> 28800
A13: Engineer/ Discipline Specialist | B13: C2 | C13: 33970 | D13: =C13-Table5[[#This Row],[Total Quantity]]-I28-I43-I60-I78-I97-I120-I142-I161-I273 -> -3702.03 | G13: Engineer/ Discipline Specialist | H13: C2 | I13: 15200 | J13: =Table5[[#This Row],[Total Quantity]]-Table5[[#This Row],[Quantity]]-Table5[[#This Row],[Quantity2]] -> 4511 | K13: 145 | L13: 3849 | M13: =Table5[[#This Row],[Rate]]*Table5[[#This Row],[Quantity]] -> 558105 | N13: 6840 | O13: =Table5[[#This Row],[Quantity2]]*Table5[[#This Row],[Rate]] -> 991800 | P13: 3751 | Q13: =Table5[[#This Row],[Rate]]*Table5[[#This Row],[Quantity3]] -> 543895 | R13: 760 | S13: =Table5[[#This Row],[Quantity25]]*Table5[[#This Row],[Rate]] -> 110200
A14: Draftsman | B14: D2 | C14: 36820 | D14: =C14-Table5[[#This Row],[Total Quantity]]-I29-I44-I61-I79-I98-I121-I143-I162 -> -10720.06 | G14: Draftsman | H14: D2 | I14: 13235 | J14: =Table5[[#This Row],[Total Quantity]]-Table5[[#This Row],[Quantity]]-Table5[[#This Row],[Quantity2]] -> 1342.8 | K14: 82 | L14: 7657 | M14: =Table5[[#This Row],[Rate]]*Table5[[#This Row],[Quantity]] -> 627874 | N14: 4235.2 | O14: =Table5[[#This Row],[Quantity2]]*Table5[[#This Row],[Rate]] -> 347286.4 | P14: 681.05 | Q14: =Table5[[#This Row],[Rate]]*Table5[[#This Row],[Quantity3]] -> 55846.1 | R14: 661.75 | S14: =Table5[[#This Row],[Quantity25]]*Table5[[#This Row],[Rate]] -> 54263.5
A15: E2/ Project Manager | B15: E2 | C15: 7140 | D15: =C15-Table5[[#This Row],[Total Quantity]]-I30-I45-I275 -> 7140 | G15: E2/ Project Manager | H15: E2 | J15: =Table5[[#This Row],[Total Quantity]]-Table5[[#This Row],[Quantity]]-Table5[[#This Row],[Quantity2]] -> 0 | K15: 275 | M15: =Table5[[#This Row],[Quantity2]]*Table5[[#This Row],[Rate]] -> 0 | O15: =Table5[[#This Row],[Quantity2]]*Table5[[#This Row],[Rate]] -> 0 | Q15: =Table5[[#This Row],[Quantity2]]*Table5[[#This Row],[Rate]] -> 0 | S15: =Table5[[#This Row],[Quantity2]]*Table5[[#This Row],[Rate]] -> 0
A16: F2/ Project Manager | B16: F2 | C16: 7140 | D16: =C16-Table5[[#This Row],[Total Quantity]]-I31-I46-I276 -> 7140 | G16: F2/ Project Manager | H16: F2 | J16: =Table5[[#This Row],[Total Quantity]]-Table5[[#This Row],[Quantity]]-Table5[[#This Row],[Quantity2]] -> 0 | K16: 180 | M16: =Table5[[#This Row],[Quantity2]]*Table5[[#This Row],[Rate]] -> 0 | O16: =Table5[[#This Row],[Quantity2]]*Table5[[#This Row],[Rate]] -> 0 | Q16: =Table5[[#This Row],[Quantity2]]*Table5[[#This Row],[Rate]] -> 0 | S16: =Table5[[#This Row],[Quantity2]]*Table5[[#This Row],[Rate]] -> 0
K17: Total | L17: =SUM(L7:L16) -> 12535.05 | M17: =SUM(M7:M16) -> 1395290.5 | N17: =SUM(N7:N16) -> 13532.182 | O17: =SUM(O7:O16) -> 1874916.4 | P17: =SUM(P7:P16) -> 5696.0182 | Q17: =SUM(Q7:Q16) -> 872049.61 | R17: =SUM(R7:R16) -> 1671.75 | S17: =SUM(S7:S16) -> 218013.5
U19: VO
G20: Project support services | L20: Invoice 1 | N20: Invoice 2 | P20: Invoice 4 | T20: Invoice 7 | V20: Invoice 11
G21: Description | H21: Category | I21: Total Quantity | J21: Remaining quantity | K21: Rate | L21: Quantity | M21: Amount | N21: Quantity2 | O21: Amount3 | P21: Quantity22 | Q21: Amount33 | R21: Column1 | S21: Column2 | T21: Quantity2222 | U21: Amount3333 | V21: Quantity22222 | W21: Amount33333
D22: =K12/5421 -> 0.033204206 | G22: Lead Engineer/ Discipline Engineer | H22: A1 | J22: =Table57[[#This Row],[Total Quantity]]-Table57[[#This Row],[Quantity2222]] -> 0 | K22: 465 | M22: =Table57[[#This Row],[Quantity2222]]*Table57[[#This Row],[Rate]] -> 0 | O22: =Table57[[#This Row],[Quantity2222]]*Table57[[#This Row],[Rate]] -> 0 | Q22: =Table57[[#This Row],[Quantity2222]]*Table57[[#This Row],[Rate]] -> 0 | U22: =Table57[[#This Row],[Quantity2222]]*Table57[[#This Row],[Rate]] -> 0 | W22: =Table57[[#This Row],[Quantity2222]]*Table57[[#This Row],[Rate]] -> 0
G23: Sr. Engineer/ Senior discipline specialist | H23: B1 | J23: =Table57[[#This Row],[Total Quantity]]-Table57[[#This Row],[Quantity2222]] -> 0 | K23: 390 | M23: =Table57[[#This Row],[Quantity2222]]*Table57[[#This Row],[Rate]] -> 0 | O23: =Table57[[#This Row],[Quantity2222]]*Table57[[#This Row],[Rate]] -> 0 | Q23: =Table57[[#This Row],[Quantity2222]]*Table57[[#This Row],[Rate]] -> 0 | U23: =Table57[[#This Row],[Quantity2222]]*Table57[[#This Row],[Rate]] -> 0 | W23: =Table57[[#This Row],[Quantity2222]]*Table57[[#This Row],[Rate]] -> 0
C24: 1488300 | D24: =C24/K12 -> 8268.3333 | G24: Engineer/ Discipline Specialist | H24: C1 | J24: =Table57[[#This Row],[Total Quantity]]-Table57[[#This Row],[Quantity2222]] -> 0 | K24: 200 | M24: =Table57[[#This Row],[Quantity2222]]*Table57[[#This Row],[Rate]] -> 0 | O24: =Table57[[#This Row],[Quantity2222]]*Table57[[#This Row],[Rate]] -> 0 | Q24: =Table57[[#This Row],[Quantity2222]]*Table57[[#This Row],[Rate]] -> 0 | U24: =Table57[[#This Row],[Quantity2222]]*Table57[[#This Row],[Rate]] -> 0 | W24: =Table57[[#This Row],[Quantity2222]]*Table57[[#This Row],[Rate]] -> 0
